# 介绍

- 在默认情况下，当发生错误后(panic),程序就会退出（崩溃.）
- 当发生错误后
  - 捕获到错误，并进行处理，保证程序可以继续执行
  - 捕获到错误后，给一个提示

- Go语言不支持传统的try...catch...finally这种处理
- Go中引入的处理方式为
  - defer
  - panic
  - recover
- go可抛出一个panic异常，然后defer中通过recover捕获这个异常，并处理这个异常



# defer+recover 处理错误

- 使用defer 定义一个延时匿名函数，使用recover获取到异常信息，进行处理
- 实现类似于try...catch机制

```go
package main
import (
	"time"
	"fmt"
)
func main(){
	// 测试
	f()
	for{
		fmt.Println("模拟main继续执行")
		time.Sleep(time.Second)
	}
}

func f(){
	// 定义延时匿名函数，用于对异常的处理
	// 如果有异常则会正常执行该函数
	defer func(){
		err := recover() // 内置函数，捕获异常
		if err != nil {
			fmt.Println("err=",err)
            // 可以对该异常做其他处理，如记录日志等
		}
	}()
	n := 10
	m := 0
	res := n / m
	fmt.Println("res=",res)
}
// 结果
err= runtime error: integer divide by zero
模拟main继续执行
模拟main继续执行
```

- 好处：进行错误处理后，程序不会轻易挂掉，如果加入预警代码，就可以让程序更加的健壮



# 自定义错误

- Go支持自定义错误，使用errors.New和panic内置函数
- errors.New("错误说明")，会返回一个error类型的值，表示一个错误
- panic内置函数,接收一个interface{}类型的值（也就是任何值了）作为参数
  - 可以接收error类型的变量，==输出错误信息，并退出程序==

```go
package main
import (
	"errors"
	"fmt"
)
func main(){

	err := readConf("conf.ini")
	if err != nil {
		// 如果有错误，输出该错误，并终止程序
		// panic会终止程序执行
		panic(err)
	}
	fmt.Println("main ...")
}

func readConf(name string) (err error) {
	if name == "config.ini" {
		// 读取文件
		return nil
	} else {
		// 返回一个自定义错误
		return errors.New("文件名错误")
	}
}
// 结果
panic: 文件名错误

goroutine 1 [running]:
main.main()
        D:/go/gopath/src/demo/main/test.go:12 +0xff
exit status 2
```

